Workbook

Sheet Academic
J1: No. of Teachers | K1: No. of Students
I2: 51 - St. nicholas International Schools, Pelawatta, Colombo | J2: =COUNTIF(B10:B1048576,51) -> 38 | W2: =DATE(V2,U2,T2) -> #NUM!
I3: 52 - St. Nicholas International School, Negombo | J3: =COUNTIF(B10:B1048576,52) -> 112
I4: 53 - St. Thomas International School, Seeduwa | J4: =COUNTIF(B10:B1048576,53) -> 132 | K4: COUNTIF(B16:B1048576,51) 52, 53, 54 | AB4: 60 years | AC4: 21915 days
I5: 54 - St. Michelle's College, Negombo | J5: =COUNTIF(B10:B1048576,54) -> 22 | L5: Over 60 y
L6: 59 - 60 y
G7: =TODAY() -> 46027 | I7: Total No. of Teachers | J7: =SUM(J2:J5) -> 304
A8: Personal Identification Number | E8: Teacher Identification Number (TIN) | F8: Present Category (Confirmed/Contract) | G8: Name in Full | H8: Designation | I8: Home Address | J8: NIC Number | K8: Religion | L8: Telephone Numbers | M8: Email | N8: Date of Birth | T8: Date of First Appointment | Z8: Present Service | AC8: Present Service | AD8: Retirement Date | AM8: GM's Interview and Confirmation Letter | AO8: Confirmation effective from | AP8: No conrimation letter | AQ8: Fixed Term Contract -006 | AR8: Temporary Cadre 007 | AS8: No File | AT8: Resigned
N9: Date | O9: Month | P9: Year | Q9: Date of Birth | R9: Age | T9: Date | U9: Month | V9: Year | W9: Date of First Appointment | Z9: Years | AA9: Months | AB9: Days | AE9: Years | AF9: Months | AG9: Days | AJ9: Years | AK9: Months | AL9: Days | AM9: Interviewed on | AN9: Appointment Effective from | AO9: Confirmation effective from
A10: 1 | B10: 051 | C10: 001 | D10: 0001 | E10: =CONCATENATE(A10,"/",B10,"/",C10,"/",D10) -> 1/051/001/0001 | F10: Confirmed | G10: Rev. Fr. Samith Rangana | H10: Rector | I10: St. John Dal Bastone Church, Church Rd, Pelawatte, Battaramulla | K10: Roman Catholic | S10: Male | T10: 25 | U10: 10 | V10: 2023 | W10: =DATE(V10,U10,T10) -> 45224 | X10: Yes
A11: 1 | B11: 051 | C11: 002 | D11: 0002 | E11: =CONCATENATE(A11,"/",B11,"/",C11,"/",D11) -> 1/051/002/0002 | F11: Contract | G11: Rev. Sr. Clotilda Fernando | H11: Teacher | I11: Sisters of the Cross, Havelock Rd, Col 5 | J11: 517420328V | K11: Roman Catholic | L11: 0711640880 | M11: clotildafernando@gmail.com | N11: 29 | O11: 08 | P11: 1951 | Q11: =DATE(P11,O11,N11) -> 18869 | R11: =($G$7-Q11)/365 -> 74.405479 | S11: Female | T11: 02 | U11: 09 | V11: 2019 | W11: =DATE(V11,U11,T11) -> 43710 | X11: Yes | Y11: Yes | Z11: =DATEDIF(W11,G7,"Y") -> 6 | AA11: =DATEDIF(W11,G7,"YM") -> 4 | AB11: =DATEDIF(W11,TODAY(),"MD") -> 3 | AC11: =CONCATENATE(Z11,"Years","/",,AA11,"Months","/",AB11,"Days") -> 6Years/4Months/3Days | AD11: =(DATE(P11,O11,N11)+21915) -> 40784 | AE11: =DATEDIF(TODAY(),AD11,"Y") -> #NUM! | AF11: =DATEDIF(TODAY(),AD11,"YM") -> #NUM! | AG11: =DATEDIF(TODAY(),AD11,"MD") -> #NUM! | AH11: =CONCATENATE(AE11,"Years","/",AF11,"Months","/",AG11,"Days") -> #NUM! | AI11: =CONCATENATE(AJ11,"years", " ",",", " ",AK11,"months ","and"," ",AL11,"days") -> #NUM! | AJ11: =DATEDIF(W11,AD11,"Y") -> #NUM! | AK11: =DATEDIF(W11,AD11,"YM") -> #NUM! | AL11: =DATEDIF(W11,AD11,"MD") -> #NUM!
A12: 1 | B12: 051 | C12: 003 | D12: 0003 | E12: =CONCATENATE(A12,"/",B12,"/",C12,"/",D12) -> 1/051/003/0003 | F12: Probation | G12: Rev. Sr. Thanuja Fernandopulle | H12: Teacher | I12: Bethany house, Thalangama South, Pelawatte, Battaramulla | J12: 977243793V | K12: Roman Catholic | L12: 07423525877 | M12: stthanuja1997@gmail.com | N12: 11 | O12: 08 | P12: 1997 | Q12: =DATE(P12,O12,N12) -> 35653 | R12: =($G$7-Q12)/365 -> 28.421918 | S12: Female | T12: 03 | U12: 01 | V12: 2023 | W12: =DATE(V12,U12,T12) -> 44929 | X12: No | Z12: =DATEDIF(W12,G7,"Y") -> 3 | AA12: =DATEDIF(W12,G7,"YM") -> 0 | AB12: =DATEDIF(W12,TODAY(),"MD") -> 2 | AC12: =CONCATENATE(Z12,"Years","/",,AA12,"Months","/",AB12,"Days") -> 3Years/0Months/2Days | AD12: =(DATE(P12,O12,N12)+21915) -> 57568 | AE12: =DATEDIF(TODAY(),AD12,"Y") -> 31 | AF12: =DATEDIF(TODAY(),AD12,"YM") -> 7 | AG12: =DATEDIF(TODAY(),AD12,"MD") -> 6 | AH12: =CONCATENATE(AE12,"Years","/",AF12,"Months","/",AG12,"Days") -> 31Years/7Months/6Days | AI12: =CONCATENATE(AJ12,"years", " ",",", " ",AK12,"months ","and"," ",AL12,"days") -> 34years , 7months and 8days | AJ12: =DATEDIF(W12,AD12,"Y") -> 34 | AK12: =DATEDIF(W12,AD12,"YM") -> 7 | AL12: =DATEDIF(W12,AD12,"MD") -> 8
A13: 1 | B13: 051 | C13: 004 | D13: 0004 | E13: =CONCATENATE(A13,"/",B13,"/",C13,"/",D13) -> 1/051/004/0004 | G13: Rebecca Juliana Pavey | H13: Teacher | I13: No. 44, Rajamahavihara Road, Pita Kotte, Kotte | J13: 200165410135 | K13: Roman Catholic | L13: 741217723 | M13: rebeccajuliana.p@gmail.com | N13: 2 | O13: 6 | P13: 2001 | Q13: =DATE(P13,O13,N13) -> 37044 | R13: =($G$7-Q13)/365 -> 24.610959 | S13: Female | T13: 19 | U13: 5 | V13: 2025 | W13: =DATE(V13,U13,T13) -> 45796 | Z13: =DATEDIF(#REF!,TODAY(),"Y") -> #REF! | AA13: =DATEDIF(#REF!,TODAY(),"YM") -> #REF! | AB13: =DATEDIF(#REF!,TODAY(),"MD") -> #REF! | AC13: =CONCATENATE(Z13,"Years","/",,AA13,"Months","/",AB13,"Days") -> #REF! | AD13: =(DATE(P13,O13,N13)+21915) -> 58959 | AE13: =DATEDIF(TODAY(),AD13,"Y") -> 35 | AF13: =DATEDIF(TODAY(),AD13,"YM") -> 4 | AG13: =DATEDIF(TODAY(),AD13,"MD") -> 28 | AH13: =CONCATENATE(AE13,"Years","/",AF13,"Months","/",AG13,"Days") -> 35Years/4Months/28Days | AI13: =CONCATENATE(AJ13,"years", " ",",", " ",AK13,"months ","and"," ",AL13,"days") -> 36years , 0months and 14days | AJ13: =DATEDIF(W13,AD13,"Y") -> 36 | AK13: =DATEDIF(W13,AD13,"YM") -> 0 | AL13: =DATEDIF(W13,AD13,"MD") -> 14
A14: 1 | B14: 051 | C14: 005 | D14: 0005 | E14: =CONCATENATE(A14,"/",B14,"/",C14,"/",D14) -> 1/051/005/0005 | F14: Contract | G14: F. R. Ludowyke | H14: Teacher | I14: 60/2, Shalawa Road, Mirihana, Nugegoda | J14: 566196885v | K14: Roman Catholic | L14: 0774959348 | M14: franciscaludowyke@gmail.com | N14: 28 | O14: 04 | P14: 1956 | Q14: =DATE(P14,O14,N14) -> 20573 | R14: =($G$7-Q14)/365 -> 69.736986 | S14: Female | T14: 01 | U14: 01 | V14: 2014 | W14: =DATE(V14,U14,T14) -> 41640 | X14: Yes | Y14: Yes | Z14: =DATEDIF(W14,TODAY(),"Y") -> 12 | AA14: =DATEDIF(W14,TODAY(),"YM") -> 0 | AB14: =DATEDIF(W14,TODAY(),"MD") -> 4 | AC14: =CONCATENATE(Z14,"Years","/",,AA14,"Months","/",AB14,"Days") -> 12Years/0Months/4Days | AD14: =(DATE(P14,O14,N14)+21915) -> 42488 | AH14: =CONCATENATE(AE14,"Years","/",AF14,"Months","/",AG14,"Days") -> Years/Months/Days | AI14: =CONCATENATE(AJ14,"years", " ",",", " ",AK14,"months ","and"," ",AL14,"days") -> 2years , 3months and 27days | AJ14: =DATEDIF(W14,AD14,"Y") -> 2 | AK14: =DATEDIF(W14,AD14,"YM") -> 3 | AL14: =DATEDIF(W14,AD14,"MD") -> 27
A15: 1 | B15: 051 | C15: 006 | D15: 0006 | E15: =CONCATENATE(A15,"/",B15,"/",C15,"/",D15) -> 1/051/006/0006 | F15: Contract | G15: Mirani Dissanayake | H15: Teacher | I15: 6/15, Church Gardens, Mahamegawatte, Maharagama | J15: 525761509v | K15: Roman Catholic | L15: 0776571788 | M15: hycinth.mirani@gmail.com | N15: 16 | O15: 03 | P15: 1952 | Q15: =DATE(P15,O15,N15) -> 19069 | R15: =($G$7-Q15)/365 -> 73.857534 | S15: Female | T15: 01 | U15: 04 | V15: 2013 | W15: =DATE(V15,U15,T15) -> 41365 | X15: Yes | Y15: Yes | Z15: =DATEDIF(W15,TODAY(),"Y") -> 12 | AA15: =DATEDIF(W15,TODAY(),"YM") -> 9 | AB15: =DATEDIF(W15,TODAY(),"MD") -> 4 | AC15: =CONCATENATE(Z15,"Years","/",,AA15,"Months","/",AB15,"Days") -> 12Years/9Months/4Days | AD15: =(DATE(P15,O15,N15)+21915) -> 40984 | AE15: =DATEDIF(TODAY(),AD15,"Y") -> #NUM! | AF15: =DATEDIF(TODAY(),AD15,"YM") -> #NUM! | AG15: =DATEDIF(TODAY(),AD15,"MD") -> #NUM! | AH15: =CONCATENATE(AE15,"Years","/",AF15,"Months","/",AG15,"Days") -> #NUM! | AI15: =CONCATENATE(AJ15,"years", " ",",", " ",AK15,"months ","and"," ",AL15,"days") -> #NUM! | AJ15: =DATEDIF(W15,AD15,"Y") -> #NUM! | AK15: =DATEDIF(W15,AD15,"YM") -> #NUM! | AL15: =DATEDIF(W15,AD15,"MD") -> #NUM!
A16: 1 | B16: 051 | C16: 007 | D16: 0007 | E16: =CONCATENATE(A16,"/",B16,"/",C16,"/",D16) -> 1/051/007/0007 | F16: Confirmed | G16: Prasanna Samarawickrama | H16: Teacher | I16: 6/23, Albion Lane, Colombo 9 | J16: 663390260v | K16: Buddhist | L16: 0771935348 | M16: prasannasa@gmail.com | N16: 04 | O16: 12 | P16: 1966 | Q16: =DATE(P16,O16,N16) -> 24445 | R16: =($G$7-Q16)/365 -> 59.128767 | S16: Male | T16: 14 | U16: 01 | V16: 2013 | W16: =DATE(V16,U16,T16) -> 41288 | X16: Yes | Z16: =DATEDIF(W16,TODAY(),"Y") -> 12 | AA16: =DATEDIF(W16,TODAY(),"YM") -> 11 | AB16: =DATEDIF(W16,TODAY(),"MD") -> 22 | AC16: =CONCATENATE(Z16,"Years","/",,AA16,"Months","/",AB16,"Days") -> 12Years/11Months/22Days | AD16: =(DATE(P16,O16,N16)+21915) -> 46360 | AE16: =DATEDIF(TODAY(),AD16,"Y") -> 0 | AF16: =DATEDIF(TODAY(),AD16,"YM") -> 10 | AG16: =DATEDIF(TODAY(),AD16,"MD") -> 29 | AH16: =CONCATENATE(AE16,"Years","/",AF16,"Months","/",AG16,"Days") -> 0Years/10Months/29Days | AI16: =CONCATENATE(AJ16,"years", " ",",", " ",AK16,"months ","and"," ",AL16,"days") -> 13years , 10months and 20days | AJ16: =DATEDIF(W16,AD16,"Y") -> 13 | AK16: =DATEDIF(W16,AD16,"YM") -> 10 | AL16: =DATEDIF(W16,AD16,"MD") -> 20
A17: 1 | B17: 051 | C17: 008 | D17: 0008 | E17: =CONCATENATE(A17,"/",B17,"/",C17,"/",D17) -> 1/051/008/0008 | F17: Confirmed | G17: Nilmini Perera | H17: Teacher | I17: 37/1/1A, 1st Lane, Dambawela Rd, Ampitiya, Kandy | J17: 828022652v | K17: Roman Catholic | L17: 0772847282 | M17: Nilmini28@gmail.com | N17: 28 | O17: 10 | P17: 1982 | Q17: =DATE(P17,O17,N17) -> 30252 | R17: =($G$7-Q17)/365 -> 43.219178 | S17: Female | T17: 23 | U17: 09 | V17: 2013 | W17: =DATE(V17,U17,T17) -> 41540 | X17: Yes | Z17: =DATEDIF(W17,TODAY(),"Y") -> 12 | AA17: =DATEDIF(W17,TODAY(),"YM") -> 3 | AB17: =DATEDIF(W17,TODAY(),"MD") -> 13 | AC17: =CONCATENATE(Z17,"Years","/",,AA17,"Months","/",AB17,"Days") -> 12Years/3Months/13Days | AD17: =(DATE(P17,O17,N17)+21915) -> 52167 | AE17: =DATEDIF(TODAY(),AD17,"Y") -> 16 | AF17: =DATEDIF(TODAY(),AD17,"YM") -> 9 | AG17: =DATEDIF(TODAY(),AD17,"MD") -> 23 | AH17: =CONCATENATE(AE17,"Years","/",AF17,"Months","/",AG17,"Days") -> 16Years/9Months/23Days | AI17: =CONCATENATE(AJ17,"years", " ",",", " ",AK17,"months ","and"," ",AL17,"days") -> 29years , 1months and 5days | AJ17: =DATEDIF(W17,AD17,"Y") -> 29 | AK17: =DATEDIF(W17,AD17,"YM") -> 1 | AL17: =DATEDIF(W17,AD17,"MD") -> 5
A18: 1 | B18: 051 | C18: 009 | D18: 0009 | E18: =CONCATENATE(A18,"/",B18,"/",C18,"/",D18) -> 1/051/009/0009 | F18: Confirmed | G18: Nemini Wanigasekara | H18: Teacher | I18: 16/1, Bakmeegolla, Ibbagamuwa | J18: 908500326v | K18: Roman Catholic | L18: 0773015501 | M18: nemini.snic@gmail.com | N18: 15 | O18: 12 | P18: 1990 | Q18: =DATE(P18,O18,N18) -> 33222 | R18: =($G$7-Q18)/365 -> 35.082192 | S18: Female | T18: 03 | U18: 11 | V18: 2014 | W18: =DATE(V18,U18,T18) -> 41946 | X18: Yes | Z18: =DATEDIF(W18,TODAY(),"Y") -> 11 | AA18: =DATEDIF(W18,TODAY(),"YM") -> 2 | AB18: =DATEDIF(W18,TODAY(),"MD") -> 2 | AC18: =CONCATENATE(Z18,"Years","/",,AA18,"Months","/",AB18,"Days") -> 11Years/2Months/2Days | AD18: =(DATE(P18,O18,N18)+21915) -> 55137 | AE18: =DATEDIF(TODAY(),AD18,"Y") -> 24 | AF18: =DATEDIF(TODAY(),AD18,"YM") -> 11 | AG18: =DATEDIF(TODAY(),AD18,"MD") -> 10 | AH18: =CONCATENATE(AE18,"Years","/",AF18,"Months","/",AG18,"Days") -> 24Years/11Months/10Days | AI18: =CONCATENATE(AJ18,"years", " ",",", " ",AK18,"months ","and"," ",AL18,"days") -> 36years , 1months and 12days | AJ18: =DATEDIF(W18,AD18,"Y") -> 36 | AK18: =DATEDIF(W18,AD18,"YM") -> 1 | AL18: =DATEDIF(W18,AD18,"MD") -> 12
A19: 1 | B19: 051 | C19: 010 | D19: 0010 | E19: =CONCATENATE(A19,"/",B19,"/",C19,"/",D19) -> 1/051/010/0010 | F19: Confirmed | G19: Marietta Hingert | H19: Teacher | J19: 866331669v | K19: Roman Catholic | L19: 0766783274 | M19: mariettahing@gmail.com | N19: 12 | O19: 05 | P19: 1986 | Q19: =DATE(P19,O19,N19) -> 31544 | R19: =($G$7-Q19)/365 -> 39.679452 | S19: Female | T19: 04 | U19: 01 | V19: 2016 | W19: =DATE(V19,U19,T19) -> 42373 | X19: Yes | Z19: =DATEDIF(W19,TODAY(),"Y") -> 10 | AA19: =DATEDIF(W19,TODAY(),"YM") -> 0 | AB19: =DATEDIF(W19,TODAY(),"MD") -> 1 | AC19: =CONCATENATE(Z19,"Years","/",,AA19,"Months","/",AB19,"Days") -> 10Years/0Months/1Days | AD19: =(DATE(P19,O19,N19)+21915) -> 53459 | AE19: =DATEDIF(TODAY(),AD19,"Y") -> 20 | AF19: =DATEDIF(TODAY(),AD19,"YM") -> 4 | AG19: =DATEDIF(TODAY(),AD19,"MD") -> 7 | AH19: =CONCATENATE(AE19,"Years","/",AF19,"Months","/",AG19,"Days") -> 20Years/4Months/7Days | AI19: =CONCATENATE(AJ19,"years", " ",",", " ",AK19,"months ","and"," ",AL19,"days") -> 30years , 4months and 8days | AJ19: =DATEDIF(W19,AD19,"Y") -> 30 | AK19: =DATEDIF(W19,AD19,"YM") -> 4 | AL19: =DATEDIF(W19,AD19,"MD") -> 8
A20: 1 | B20: 051 | C20: 011 | D20: 0011 | E20: =CONCATENATE(A20,"/",B20,"/",C20,"/",D20) -> 1/051/011/0011 | F20: Confirmed | G20: Gayathri Arasaratnam | H20: Teacher | I20: 12-1/5, Station Rd, Wellawatte, Colombo 6 | J20: 808213109v | K20: Hindu | L20: 0776943137 | M20: gayaoneness@gmail.com | N20: 16 | O20: 11 | P20: 1980 | Q20: =DATE(P20,O20,N20) -> 29541 | R20: =($G$7-Q20)/365 -> 45.167123 | S20: Female | T20: 28 | U20: 04 | V20: 2016 | W20: =DATE(V20,U20,T20) -> 42488 | X20: Yes | Z20: =DATEDIF(W20,TODAY(),"Y") -> 9 | AA20: =DATEDIF(W20,TODAY(),"YM") -> 8 | AB20: =DATEDIF(W20,TODAY(),"MD") -> 8 | AC20: =CONCATENATE(Z20,"Years","/",,AA20,"Months","/",AB20,"Days") -> 9Years/8Months/8Days | AD20: =(DATE(P20,O20,N20)+21915) -> 51456 | AE20: =DATEDIF(TODAY(),AD20,"Y") -> 14 | AF20: =DATEDIF(TODAY(),AD20,"YM") -> 10 | AG20: =DATEDIF(TODAY(),AD20,"MD") -> 11 | AH20: =CONCATENATE(AE20,"Years","/",AF20,"Months","/",AG20,"Days") -> 14Years/10Months/11Days | AI20: =CONCATENATE(AJ20,"years", " ",",", " ",AK20,"months ","and"," ",AL20,"days") -> 24years , 6months and 19days | AJ20: =DATEDIF(W20,AD20,"Y") -> 24 | AK20: =DATEDIF(W20,AD20,"YM") -> 6 | AL20: =DATEDIF(W20,AD20,"MD") -> 19
A21: 1 | B21: 051 | C21: 012 | D21: 0012 | E21: =CONCATENATE(A21,"/",B21,"/",C21,"/",D21) -> 1/051/012/0012 | F21: Confirmed | G21: Thilashni Perera | H21: Teacher | I21: 262/2, St. Francis lane, Dalugama, Kelaniya | J21: 198364501112 | K21: Roman Catholic | L21: 0760718748 | M21: pererathilashni@gmail.com | N21: 24 | O21: 05 | P21: 1983 | Q21: =DATE(P21,O21,N21) -> 30460 | R21: =($G$7-Q21)/365 -> 42.649315 | S21: Female | T21: 01 | U21: 09 | V21: 2016 | W21: =DATE(V21,U21,T21) -> 42614 | X21: Yes | Z21: =DATEDIF(W21,TODAY(),"Y") -> 9 | AA21: =DATEDIF(W21,TODAY(),"YM") -> 4 | AB21: =DATEDIF(W21,TODAY(),"MD") -> 4 | AC21: =CONCATENATE(Z21,"Years","/",,AA21,"Months","/",AB21,"Days") -> 9Years/4Months/4Days | AD21: =(DATE(P21,O21,N21)+21915) -> 52375 | AE21: =DATEDIF(TODAY(),AD21,"Y") -> 17 | AF21: =DATEDIF(TODAY(),AD21,"YM") -> 4 | AG21: =DATEDIF(TODAY(),AD21,"MD") -> 19 | AH21: =CONCATENATE(AE21,"Years","/",AF21,"Months","/",AG21,"Days") -> 17Years/4Months/19Days | AI21: =CONCATENATE(AJ21,"years", " ",",", " ",AK21,"months ","and"," ",AL21,"days") -> 26years , 8months and 23days | AJ21: =DATEDIF(W21,AD21,"Y") -> 26 | AK21: =DATEDIF(W21,AD21,"YM") -> 8 | AL21: =DATEDIF(W21,AD21,"MD") -> 23
A22: 1 | B22: 051 | C22: 013 | D22: 0013 | E22: =CONCATENATE(A22,"/",B22,"/",C22,"/",D22) -> 1/051/013/0013 | F22: Confirmed | G22: R.M. Nafeel | H22: Teacher | I22: 78, Nanayakkara Mw, Rajagiriya | J22: 902421904v | K22: Muslim | L22: 0774920729 | M22: muhamednafeel@gmail.com | N22: 29 | O22: 08 | P22: 1990 | Q22: =DATE(P22,O22,N22) -> 33114 | R22: =($G$7-Q22)/365 -> 35.378082 | S22: Male | T22: 04 | U22: 09 | V22: 2017 | W22: =DATE(V22,U22,T22) -> 42982 | X22: Yes | Z22: =DATEDIF(W22,TODAY(),"Y") -> 8 | AA22: =DATEDIF(W22,TODAY(),"YM") -> 4 | AB22: =DATEDIF(W22,TODAY(),"MD") -> 1 | AC22: =CONCATENATE(Z22,"Years","/",,AA22,"Months","/",AB22,"Days") -> 8Years/4Months/1Days | AD22: =(DATE(P22,O22,N22)+21915) -> 55029 | AE22: =DATEDIF(TODAY(),AD22,"Y") -> 24 | AF22: =DATEDIF(TODAY(),AD22,"YM") -> 7 | AG22: =DATEDIF(TODAY(),AD22,"MD") -> 24 | AH22: =CONCATENATE(AE22,"Years","/",AF22,"Months","/",AG22,"Days") -> 24Years/7Months/24Days | AI22: =CONCATENATE(AJ22,"years", " ",",", " ",AK22,"months ","and"," ",AL22,"days") -> 32years , 11months and 25days | AJ22: =DATEDIF(W22,AD22,"Y") -> 32 | AK22: =DATEDIF(W22,AD22,"YM") -> 11 | AL22: =DATEDIF(W22,AD22,"MD") -> 25
A23: 1 | B23: 051 | C23: 014 | D23: 0014 | E23: =CONCATENATE(A23,"/",B23,"/",C23,"/",D23) -> 1/051/014/0014 | F23: Probation | G23: Samanthi Sujeewa Perera | H23: Teacher | I23: No. 435/B1, Thalangama South, Akuregoda, Battramulla | J23: 708521833V | K23: Buddhist | L23: 718182371 | M23: samanthi.sperera@gmail.com | N23: 17 | O23: 12 | P23: 1970 | Q23: =DATE(P23,O23,N23) -> 25919 | R23: =($G$7-Q23)/365 -> 55.090411 | S23: Female | T23: 01 | U23: 09 | V23: 2025 | W23: =DATE(V23,U23,T23) -> 45901 | Z23: =DATEDIF(W23,TODAY(),"Y") -> 0 | AA23: =DATEDIF(W23,TODAY(),"YM") -> 4 | AB23: =DATEDIF(W23,TODAY(),"MD") -> 4 | AC23: =CONCATENATE(Z23,"Years","/",,AA23,"Months","/",AB23,"Days") -> 0Years/4Months/4Days | AD23: =(DATE(P23,O23,N23)+21915) -> 47834 | AE23: =DATEDIF(TODAY(),AD23,"Y") -> 4 | AF23: =DATEDIF(TODAY(),AD23,"YM") -> 11 | AG23: =DATEDIF(TODAY(),AD23,"MD") -> 12 | AH23: =CONCATENATE(AE23,"Years","/",AF23,"Months","/",AG23,"Days") -> 4Years/11Months/12Days | AI23: =CONCATENATE(AJ23,"years", " ",",", " ",AK23,"months ","and"," ",AL23,"days") -> 5years , 3months and 16days | AJ23: =DATEDIF(W23,AD23,"Y") -> 5 | AK23: =DATEDIF(W23,AD23,"YM") -> 3 | AL23: =DATEDIF(W23,AD23,"MD") -> 16 | AT23: Resigned
A24: 1 | B24: 051 | C24: 015 | D24: 0015 | E24: =CONCATENATE(A24,"/",B24,"/",C24,"/",D24) -> 1/051/015/0015 | F24: Probation | G24: Weerakoon Mohottige Nushari Maleesha | H24: Teacher | I24: 944/18, Municipal Council Road, Battaramulla | J24: 199786210020 | K24: Roman Catholic | L24: 775882870 | M24: nushariweerakoon@gmail.com | N24: 27 | O24: 12 | P24: 1997 | Q24: =DATE(P24,O24,N24) -> 35791 | R24: =($G$7-Q24)/365 -> 28.043836 | S24: Female | T24: 12 | U24: 09 | V24: 2025 | W24: =DATE(V24,U24,T24) -> 45912 | Z24: =DATEDIF(W24,TODAY(),"Y") -> 0 | AA24: =DATEDIF(W24,TODAY(),"YM") -> 3 | AB24: =DATEDIF(W24,TODAY(),"MD") -> 24 | AC24: =CONCATENATE(Z24,"Years","/",,AA24,"Months","/",AB24,"Days") -> 0Years/3Months/24Days | AD24: =(DATE(P24,O24,N24)+21915) -> 57706 | AE24: =DATEDIF(TODAY(),AD24,"Y") -> 31 | AF24: =DATEDIF(TODAY(),AD24,"YM") -> 11 | AG24: =DATEDIF(TODAY(),AD24,"MD") -> 22 | AH24: =CONCATENATE(AE24,"Years","/",AF24,"Months","/",AG24,"Days") -> 31Years/11Months/22Days | AI24: =CONCATENATE(AJ24,"years", " ",",", " ",AK24,"months ","and"," ",AL24,"days") -> 32years , 3months and 15days | AJ24: =DATEDIF(W24,AD24,"Y") -> 32 | AK24: =DATEDIF(W24,AD24,"YM") -> 3 | AL24: =DATEDIF(W24,AD24,"MD") -> 15
A25: 1 | B25: 051 | C25: 016 | D25: 0016 | E25: =CONCATENATE(A25,"/",B25,"/",C25,"/",D25) -> 1/051/016/0016 | F25: Contract | G25: Radha Jayawardena | H25: Teacher | I25: 107/31, Shalawa Rd, Mirihana, Nugegoda | J25: 497303958v | K25: Roman Catholic | L25: 0718293573 | M25: radharanjani@ymail.com | N25: 17 | O25: 08 | P25: 1949 | Q25: =DATE(P25,O25,N25) -> 18127 | R25: =($G$7-Q25)/365 -> 76.438356 | S25: Female | T25: 02 | U25: 03 | V25: 2020 | W25: =DATE(V25,U25,T25) -> 43892 | X25: No | Y25: Yes | Z25: =DATEDIF(W25,TODAY(),"Y") -> 5 | AA25: =DATEDIF(W25,TODAY(),"YM") -> 10 | AB25: =DATEDIF(W25,TODAY(),"MD") -> 3 | AC25: =CONCATENATE(Z25,"Years","/",,AA25,"Months","/",AB25,"Days") -> 5Years/10Months/3Days | AD25: =(DATE(P25,O25,N25)+21915) -> 40042 | AE25: =DATEDIF(TODAY(),AD25,"Y") -> #NUM! | AF25: =DATEDIF(TODAY(),AD25,"YM") -> #NUM! | AG25: =DATEDIF(TODAY(),AD25,"MD") -> #NUM! | AH25: =CONCATENATE(AE25,"Years","/",AF25,"Months","/",AG25,"Days") -> #NUM! | AI25: =CONCATENATE(AJ25,"years", " ",",", " ",AK25,"months ","and"," ",AL25,"days") -> #NUM! | AJ25: =DATEDIF(W25,AD25,"Y") -> #NUM! | AK25: =DATEDIF(W25,AD25,"YM") -> #NUM! | AL25: =DATEDIF(W25,AD25,"MD") -> #NUM!
A26: 1 | B26: 051 | C26: 017 | D26: 0017 | E26: =CONCATENATE(A26,"/",B26,"/",C26,"/",D26) -> 1/051/017/0017 | F26: Probation | G26: Kylie Goonetilleke | H26: Teacher | I26: 1044/6, Ranmal Mw, Pothuarawa Rd, Malabe | J26: 905642057v | K26: Roman Catholic | L26: 0769211990 | M26: kyliegoonetilleke90@gmail.com | N26: 04 | O26: 03 | P26: 1990 | Q26: =DATE(P26,O26,N26) -> 32936 | R26: =($G$7-Q26)/365 -> 35.865753 | S26: Female | T26: 07 | U26: 02 | V26: 2022 | W26: =DATE(V26,U26,T26) -> 44599 | X26: No | Y26: Yes | Z26: =DATEDIF(W26,TODAY(),"Y") -> 3 | AA26: =DATEDIF(W26,TODAY(),"YM") -> 10 | AB26: =DATEDIF(W26,TODAY(),"MD") -> 29 | AC26: =CONCATENATE(Z26,"Years","/",,AA26,"Months","/",AB26,"Days") -> 3Years/10Months/29Days | AD26: =(DATE(P26,O26,N26)+21915) -> 54851 | AE26: =DATEDIF(TODAY(),AD26,"Y") -> 24 | AF26: =DATEDIF(TODAY(),AD26,"YM") -> 1 | AG26: =DATEDIF(TODAY(),AD26,"MD") -> 27 | AH26: =CONCATENATE(AE26,"Years","/",AF26,"Months","/",AG26,"Days") -> 24Years/1Months/27Days | AI26: =CONCATENATE(AJ26,"years", " ",",", " ",AK26,"months ","and"," ",AL26,"days") -> 28years , 0months and 25days | AJ26: =DATEDIF(W26,AD26,"Y") -> 28 | AK26: =DATEDIF(W26,AD26,"YM") -> 0 | AL26: =DATEDIF(W26,AD26,"MD") -> 25
A27: 1 | B27: 051 | C27: 018 | D27: 0018 | E27: =CONCATENATE(A27,"/",B27,"/",C27,"/",D27) -> 1/051/018/0018 | F27: Probation | G27: Lakshika Dewathanthriarachchi | H27: Teacher | I27: 187/C/5, Expo VIP City, Siyambalagoda, Polgasowita | J27: 826360070V | K27: Roman Catholic | L27: 777480715 | M27: lakshikad82@gmail.com | N27: 15 | O27: 5 | P27: 1982 | Q27: =DATE(P27,O27,N27) -> 30086 | R27: =($G$7-Q27)/365 -> 43.673973 | S27: Female | T27: 01 | U27: 10 | V27: 2025 | W27: =DATE(V27,U27,T27) -> 45931 | Z27: =DATEDIF(W27,TODAY(),"Y") -> 0 | AA27: =DATEDIF(W27,TODAY(),"YM") -> 3 | AB27: =DATEDIF(W27,TODAY(),"MD") -> 4 | AC27: =CONCATENATE(Z27,"Years","/",,AA27,"Months","/",AB27,"Days") -> 0Years/3Months/4Days | AD27: =(DATE(P27,O27,N27)+21915) -> 52001 | AE27: =DATEDIF(TODAY(),AD27,"Y") -> 16 | AF27: =DATEDIF(TODAY(),AD27,"YM") -> 4 | AG27: =DATEDIF(TODAY(),AD27,"MD") -> 10 | AH27: =CONCATENATE(AE27,"Years","/",AF27,"Months","/",AG27,"Days") -> 16Years/4Months/10Days | AI27: =CONCATENATE(AJ27,"years", " ",",", " ",AK27,"months ","and"," ",AL27,"days") -> 16years , 7months and 14days | AJ27: =DATEDIF(W27,AD27,"Y") -> 16 | AK27: =DATEDIF(W27,AD27,"YM") -> 7 | AL27: =DATEDIF(W27,AD27,"MD") -> 14
A28: 1 | B28: 051 | C28: 019 | D28: 0019 | E28: =CONCATENATE(A28,"/",B28,"/",C28,"/",D28) -> 1/051/019/0019 | F28: Contract | G28: Tamara Perera | H28: Teacher | I28: 909/11C, Adikaram Mw, Ethulkotte | J28: 647141579v | K28: Roman Catholic | L28: 0774475424 | N28: 01 | O28: 08 | P28: 1964 | Q28: =DATE(P28,O28,N28) -> 23590 | R28: =($G$7-Q28)/365 -> 61.471233 | S28: Female | T28: 02 | U28: 01 | V28: 1996 | W28: =DATE(V28,U28,T28) -> 35066 | X28: No | Y28: Yes | Z28: =DATEDIF(W28,TODAY(),"Y") -> 30 | AA28: =DATEDIF(W28,TODAY(),"YM") -> 0 | AB28: =DATEDIF(W28,TODAY(),"MD") -> 3 | AC28: =CONCATENATE(Z28,"Years","/",,AA28,"Months","/",AB28,"Days") -> 30Years/0Months/3Days | AD28: =(DATE(P28,O28,N28)+21915) -> 45505 | AE28: =DATEDIF(TODAY(),AD28,"Y") -> #NUM! | AF28: =DATEDIF(TODAY(),AD28,"YM") -> #NUM! | AG28: =DATEDIF(TODAY(),AD28,"MD") -> #NUM! | AH28: =CONCATENATE(AE28,"Years","/",AF28,"Months","/",AG28,"Days") -> #NUM! | AI28: =CONCATENATE(AJ28,"years", " ",",", " ",AK28,"months ","and"," ",AL28,"days") -> 28years , 6months and 30days | AJ28: =DATEDIF(W28,AD28,"Y") -> 28 | AK28: =DATEDIF(W28,AD28,"YM") -> 6 | AL28: =DATEDIF(W28,AD28,"MD") -> 30
A29: 1 | B29: 051 | C29: 020 | D29: 0020 | E29: =CONCATENATE(A29,"/",B29,"/",C29,"/",D29) -> 1/051/020/0020
A30: 1 | B30: 051 | C30: 021 | D30: 0021 | E30: =CONCATENATE(A30,"/",B30,"/",C30,"/",D30) -> 1/051/021/0021 | F30: Contract | G30: Shriya Wickrama | H30: Teacher | I30: 114/A 15, Udayapura, Thalangama South, Battaramulla | J30: 645934458v | K30: Roman Catholic | L30: 0777335978 | M30: shriyawickrama@gmail.com | N30: 02 | O30: 04 | P30: 1964 | Q30: =DATE(P30,O30,N30) -> 23469 | R30: =($G$7-Q30)/365 -> 61.80274 | S30: Female | T30: 21 | U30: 10 | V30: 2002 | W30: =DATE(V30,U30,T30) -> 37550 | X30: Yes | Y30: Yes | Z30: =DATEDIF(W30,TODAY(),"Y") -> 23 | AA30: =DATEDIF(W30,TODAY(),"YM") -> 2 | AB30: =DATEDIF(W30,TODAY(),"MD") -> 15 | AC30: =CONCATENATE(Z30,"Years","/",,AA30,"Months","/",AB30,"Days") -> 23Years/2Months/15Days | AD30: =(DATE(P30,O30,N30)+21915) -> 45384 | AE30: =DATEDIF(TODAY(),AD30,"Y") -> #NUM! | AF30: =DATEDIF(TODAY(),AD30,"YM") -> #NUM! | AG30: =DATEDIF(TODAY(),AD30,"MD") -> #NUM! | AH30: =CONCATENATE(AE30,"Years","/",AF30,"Months","/",AG30,"Days") -> #NUM! | AI30: =CONCATENATE(AJ30,"years", " ",",", " ",AK30,"months ","and"," ",AL30,"days") -> 21years , 5months and 12days | AJ30: =DATEDIF(W30,AD30,"Y") -> 21 | AK30: =DATEDIF(W30,AD30,"YM") -> 5 | AL30: =DATEDIF(W30,AD30,"MD") -> 12
A31: 1 | B31: 051 | C31: 022 | D31: 0022 | E31: =CONCATENATE(A31,"/",B31,"/",C31,"/",D31) -> 1/051/022/0022 | F31: Contract | G31: Antonica Fonseka | H31: Teacher | I31: 138/D, Isidoru Mw, , Thibbatugoda, Ganemulla | J31: 626154751v | K31: Roman Catholic | L31: 0704353453 | N31: 24 | O31: 04 | P31: 1962 | Q31: =DATE(P31,O31,N31) -> 22760 | R31: =($G$7-Q31)/365 -> 63.745205 | S31: Female | T31: 05 | U31: 01 | V31: 2009 | W31: =DATE(V31,U31,T31) -> 39818 | X31: Yes | Y31: Yes | Z31: =DATEDIF(W31,TODAY(),"Y") -> 17 | AA31: =DATEDIF(W31,TODAY(),"YM") -> 0 | AB31: =DATEDIF(W31,TODAY(),"MD") -> 0 | AC31: =CONCATENATE(Z31,"Years","/",,AA31,"Months","/",AB31,"Days") -> 17Years/0Months/0Days | AD31: =(DATE(P31,O31,N31)+21915) -> 44675 | AE31: =DATEDIF(TODAY(),AD31,"Y") -> #NUM! | AF31: =DATEDIF(TODAY(),AD31,"YM") -> #NUM! | AG31: =DATEDIF(TODAY(),AD31,"MD") -> #NUM! | AH31: =CONCATENATE(AE31,"Years","/",AF31,"Months","/",AG31,"Days") -> #NUM! | AI31: =CONCATENATE(AJ31,"years", " ",",", " ",AK31,"months ","and"," ",AL31,"days") -> 13years , 3months and 19days | AJ31: =DATEDIF(W31,AD31,"Y") -> 13 | AK31: =DATEDIF(W31,AD31,"YM") -> 3 | AL31: =DATEDIF(W31,AD31,"MD") -> 19
A32: 1 | B32: 051 | C32: 023 | D32: 0023 | E32: =CONCATENATE(A32,"/",B32,"/",C32,"/",D32) -> 1/051/023/0023 | F32: Confirmed | G32: Kaushila Wickramasinghe | H32: Teacher | I32: 297/1, Kalapaluwawa, Rajagiriya | J32: 757042304v | K32: Roman Catholic | L32: 0778292778 | M32: wkaushi@yahoo.com | N32: 22 | O32: 07 | P32: 1975 | Q32: =DATE(P32,O32,N32) -> 27597 | R32: =($G$7-Q32)/365 -> 50.493151 | S32: Female | T32: 20 | U32: 09 | V32: 2010 | W32: =DATE(V32,U32,T32) -> 40441 | X32: Yes | Z32: =DATEDIF(W32,TODAY(),"Y") -> 15 | AA32: =DATEDIF(W32,TODAY(),"YM") -> 3 | AB32: =DATEDIF(W32,TODAY(),"MD") -> 16 | AC32: =CONCATENATE(Z32,"Years","/",,AA32,"Months","/",AB32,"Days") -> 15Years/3Months/16Days | AD32: =(DATE(P32,O32,N32)+21915) -> 49512 | AE32: =DATEDIF(TODAY(),AD32,"Y") -> 9 | AF32: =DATEDIF(TODAY(),AD32,"YM") -> 6 | AG32: =DATEDIF(TODAY(),AD32,"MD") -> 17 | AH32: =CONCATENATE(AE32,"Years","/",AF32,"Months","/",AG32,"Days") -> 9Years/6Months/17Days | AI32: =CONCATENATE(AJ32,"years", " ",",", " ",AK32,"months ","and"," ",AL32,"days") -> 24years , 10months and 2days | AJ32: =DATEDIF(W32,AD32,"Y") -> 24 | AK32: =DATEDIF(W32,AD32,"YM") -> 10 | AL32: =DATEDIF(W32,AD32,"MD") -> 2
A33: 1 | B33: 051 | C33: 024 | D33: 0024 | E33: =CONCATENATE(A33,"/",B33,"/",C33,"/",D33) -> 1/051/024/0024 | F33: Confirmed | G33: Shanika Gunasekara | H33: Teacher | I33: 354/5, School lane, Kalapaluwawa, Rajagiriya | J33: 836293169v | K33: Buddhist | L33: 0772681628 | M33: sanodini@gmail.com | N33: 08 | O33: 05 | P33: 1983 | Q33: =DATE(P33,O33,N33) -> 30444 | R33: =($G$7-Q33)/365 -> 42.693151 | S33: Female | T33: 03 | U33: 10 | V33: 2011 | W33: =DATE(V33,U33,T33) -> 40819 | X33: Yes | Z33: =DATEDIF(W33,TODAY(),"Y") -> 14 | AA33: =DATEDIF(W33,TODAY(),"YM") -> 3 | AB33: =DATEDIF(W33,TODAY(),"MD") -> 2 | AC33: =CONCATENATE(Z33,"Years","/",,AA33,"Months","/",AB33,"Days") -> 14Years/3Months/2Days | AD33: =(DATE(P33,O33,N33)+21915) -> 52359 | AE33: =DATEDIF(TODAY(),AD33,"Y") -> 17 | AF33: =DATEDIF(TODAY(),AD33,"YM") -> 4 | AG33: =DATEDIF(TODAY(),AD33,"MD") -> 3 | AH33: =CONCATENATE(AE33,"Years","/",AF33,"Months","/",AG33,"Days") -> 17Years/4Months/3Days | AI33: =CONCATENATE(AJ33,"years", " ",",", " ",AK33,"months ","and"," ",AL33,"days") -> 31years , 7months and 5days | AJ33: =DATEDIF(W33,AD33,"Y") -> 31 | AK33: =DATEDIF(W33,AD33,"YM") -> 7 | AL33: =DATEDIF(W33,AD33,"MD") -> 5
A34: 1 | B34: 051 | C34: 025 | D34: 0025 | E34: =CONCATENATE(A34,"/",B34,"/",C34,"/",D34) -> 1/051/025/0025 | F34: Confirmed | G34: Tharini Shamika | H34: Teacher | I34: 23, Robert Goonawardena Mw, Battaramulla | J34: 200071701035 | K34: Roman Catholic | L34: 0765366330 | M34: tharinishamika@gmail.com | N34: 04 | O34: 08 | P34: 2000 | Q34: =DATE(P34,O34,N34) -> 36742 | R34: =($G$7-Q34)/365 -> 25.438356 | S34: Female | T34: 22 | U34: 09 | V34: 2021 | W34: =DATE(V34,U34,T34) -> 44461 | X34: Yes | Z34: =DATEDIF(W34,TODAY(),"Y") -> 4 | AA34: =DATEDIF(W34,TODAY(),"YM") -> 3 | AB34: =DATEDIF(W34,TODAY(),"MD") -> 14 | AC34: =CONCATENATE(Z34,"Years","/",,AA34,"Months","/",AB34,"Days") -> 4Years/3Months/14Days | AD34: =(DATE(P34,O34,N34)+21915) -> 58657 | AE34: =DATEDIF(TODAY(),AD34,"Y") -> 34 | AF34: =DATEDIF(TODAY(),AD34,"YM") -> 6 | AG34: =DATEDIF(TODAY(),AD34,"MD") -> 30 | AH34: =CONCATENATE(AE34,"Years","/",AF34,"Months","/",AG34,"Days") -> 34Years/6Months/30Days | AI34: =CONCATENATE(AJ34,"years", " ",",", " ",AK34,"months ","and"," ",AL34,"days") -> 38years , 10months and 13days | AJ34: =DATEDIF(W34,AD34,"Y") -> 38 | AK34: =DATEDIF(W34,AD34,"YM") -> 10 | AL34: =DATEDIF(W34,AD34,"MD") -> 13
A35: 1 | B35: 051 | C35: 026 | D35: 0026 | E35: =CONCATENATE(A35,"/",B35,"/",C35,"/",D35) -> 1/051/026/0026 | F35: Contract | G35: Donald Keil | H35: Teacher | I35: 363, Dehiyagatha, Jaela | J35: 512090990V | K35: Roman Catholic | L35: 0716439965 | M35: keildonald390@gmail.com | N35: 27 | O35: 07 | P35: 1951 | Q35: =DATE(P35,O35,N35) -> 18836 | R35: =($G$7-Q35)/365 -> 74.49589 | S35: Male | T35: 22 | U35: 10 | V35: 2019 | W35: =DATE(V35,U35,T35) -> 43760 | X35: Yes | Y35: Yes | Z35: =DATEDIF(W35,TODAY(),"Y") -> 6 | AA35: =DATEDIF(W35,TODAY(),"YM") -> 2 | AB35: =DATEDIF(W35,TODAY(),"MD") -> 14 | AC35: =CONCATENATE(Z35,"Years","/",,AA35,"Months","/",AB35,"Days") -> 6Years/2Months/14Days | AD35: =(DATE(P35,O35,N35)+21915) -> 40751 | AE35: =DATEDIF(TODAY(),AD35,"Y") -> #NUM! | AF35: =DATEDIF(TODAY(),AD35,"YM") -> #NUM! | AG35: =DATEDIF(TODAY(),AD35,"MD") -> #NUM! | AH35: =CONCATENATE(AE35,"Years","/",AF35,"Months","/",AG35,"Days") -> #NUM! | AI35: =CONCATENATE(AJ35,"years", " ",",", " ",AK35,"months ","and"," ",AL35,"days") -> #NUM! | AJ35: =DATEDIF(W35,AD35,"Y") -> #NUM! | AK35: =DATEDIF(W35,AD35,"YM") -> #NUM! | AL35: =DATEDIF(W35,AD35,"MD") -> #NUM!
A36: 1 | B36: 051 | C36: 027 | D36: 0027 | E36: =CONCATENATE(A36,"/",B36,"/",C36,"/",D36) -> 1/051/027/0027
A37: 1 | B37: 051 | C37: 028 | D37: 0028 | E37: =CONCATENATE(A37,"/",B37,"/",C37,"/",D37) -> 1/051/028/0028 | F37: Contract | G37: Lahiru Karunanayake | H37: Teacher | I37: 407/16Samagi Mawatha, Udahamulla, Nugegoda | J37: 843543332V | K37: Buddhist | L37: 0773694606 | M37: lahiruaioit@gmail.com | N37: 19 | O37: 12 | P37: 1984 | Q37: =DATE(P37,O37,N37) -> 31035 | R37: =($G$7-Q37)/365 -> 41.073973 | S37: Male | T37: 03 | U37: 01 | V37: 2022 | W37: =DATE(V37,U37,T37) -> 44564 | X37: No | Y37: Yes | Z37: =DATEDIF(W37,TODAY(),"Y") -> 4 | AA37: =DATEDIF(W37,TODAY(),"YM") -> 0 | AB37: =DATEDIF(W37,TODAY(),"MD") -> 2 | AC37: =CONCATENATE(Z37,"Years","/",,AA37,"Months","/",AB37,"Days") -> 4Years/0Months/2Days | AD37: =(DATE(P37,O37,N37)+21915) -> 52950 | AE37: =DATEDIF(TODAY(),AD37,"Y") -> 18 | AF37: =DATEDIF(TODAY(),AD37,"YM") -> 11 | AG37: =DATEDIF(TODAY(),AD37,"MD") -> 14 | AH37: =CONCATENATE(AE37,"Years","/",AF37,"Months","/",AG37,"Days") -> 18Years/11Months/14Days | AI37: =CONCATENATE(AJ37,"years", " ",",", " ",AK37,"months ","and"," ",AL37,"days") -> 22years , 11months and 16days | AJ37: =DATEDIF(W37,AD37,"Y") -> 22 | AK37: =DATEDIF(W37,AD37,"YM") -> 11 | AL37: =DATEDIF(W37,AD37,"MD") -> 16
A38: 1 | B38: 052 | C38: 001 | D38: 0029 | E38: =CONCATENATE(A38,"/",B38,"/",C38,"/",D38) -> 1/052/001/0029 | G38: Rev. Fr. Anthony Lakshman | H38: Rector | I38: St. Nicholas' International College, Katana Road, Nelumpitiya, Negombo | J38: 781721310v | K38: Catholic | L38: 0713547523 | M38: kdalakshman@gmail.com | N38: 20 | O38: 06 | P38: 1978 | Q38: =DATE(P38,O38,N38) -> 28661 | R38: =($G$7-Q38)/365 -> 47.578082 | S38: Male | T38: 3 | U38: 7 | V38: 2019 | W38: =DATE(V38,U38,T38) -> 43649 | Z38: =DATEDIF(W38,TODAY(),"Y") -> 6 | AA38: =DATEDIF(W38,TODAY(),"YM") -> 6 | AB38: =DATEDIF(W38,TODAY(),"MD") -> 2 | AC38: =CONCATENATE(Z38,"Years","/",,AA38,"Months","/",AB38,"Days") -> 6Years/6Months/2Days | AD38: =(DATE(P38,O38,N38)+21915) -> 50576 | AE38: =DATEDIF(TODAY(),AD38,"Y") -> 12 | AF38: =DATEDIF(TODAY(),AD38,"YM") -> 5 | AG38: =DATEDIF(TODAY(),AD38,"MD") -> 15 | AH38: =CONCATENATE(AE38,"Years","/",AF38,"Months","/",AG38,"Days") -> 12Years/5Months/15Days | AI38: =CONCATENATE(AJ38,"years", " ",",", " ",AK38,"months ","and"," ",AL38,"days") -> 18years , 11months and 17days | AJ38: =DATEDIF(W38,AD38,"Y") -> 18 | AK38: =DATEDIF(W38,AD38,"YM") -> 11 | AL38: =DATEDIF(W38,AD38,"MD") -> 17
A39: 1 | B39: 052 | C39: 002 | D39: 0030 | E39: =CONCATENATE(A39,"/",B39,"/",C39,"/",D39) -> 1/052/002/0030 | G39: Rev. Fr. Dilan Salika Perera | H39: Priest In charge of Junior School | I39: 93, Udammita, Ja Ela | J39: 930704318v | K39: Catholic | L39: 0774130725 | M39: dilansalika077@gmail.com | N39: 10 | O39: 3 | P39: 1993 | Q39: =DATE(P39,O39,N39) -> 34038 | R39: =($G$7-Q39)/365 -> 32.846575 | S39: Male | T39: 4 | U39: 10 | V39: 2022 | W39: =DATE(V39,U39,T39) -> 44838 | Z39: =DATEDIF(W39,TODAY(),"Y") -> 3 | AA39: =DATEDIF(W39,TODAY(),"YM") -> 3 | AB39: =DATEDIF(W39,TODAY(),"MD") -> 1 | AC39: =CONCATENATE(Z39,"Years","/",,AA39,"Months","/",AB39,"Days") -> 3Years/3Months/1Days | AD39: =(DATE(P39,O39,N39)+21915) -> 55953 | AE39: =DATEDIF(TODAY(),AD39,"Y") -> 27 | AF39: =DATEDIF(TODAY(),AD39,"YM") -> 2 | AG39: =DATEDIF(TODAY(),AD39,"MD") -> 5 | AH39: =CONCATENATE(AE39,"Years","/",AF39,"Months","/",AG39,"Days") -> 27Years/2Months/5Days | AI39: =CONCATENATE(AJ39,"years", " ",",", " ",AK39,"months ","and"," ",AL39,"days") -> 30years , 5months and 6days | AJ39: =DATEDIF(W39,AD39,"Y") -> 30 | AK39: =DATEDIF(W39,AD39,"YM") -> 5 | AL39: =DATEDIF(W39,AD39,"MD") -> 6
A40: 1 | B40: 052 | C40: 003 | D40: 0031 | E40: =CONCATENATE(A40,"/",B40,"/",C40,"/",D40) -> 1/052/003/0031 | G40: Rev. Fr. Tyronne Perera | H40: Spiritual director | I40: St. Nicholas' International College, Katana Road, Nelumpitiya, Negombo | K40: Catholic | S40: Male | AH40: =CONCATENATE(AE40,"Years","/",AF40,"Months","/",AG40,"Days") -> Years/Months/Days | AI40: =CONCATENATE(AJ40,"years", " ",",", " ",AK40,"months ","and"," ",AL40,"days") -> 0years , 0months and 0days | AJ40: =DATEDIF(W40,AD40,"Y") -> 0 | AK40: =DATEDIF(W40,AD40,"YM") -> 0 | AL40: =DATEDIF(W40,AD40,"MD") -> 0
...

Sheet Non-Academic
A2: Personal Identification Number | E2: Teacher Identification Number (TIN) | F2: Present Category (Confirmed/Contract) | G2: Name in Full | H2: Designation | I2: Home Address | J2: NIC Number | K2: Religion | L2: Telephone Numbers | M2: Email | N2: Date of Birth | Q2: Date of Birth | S2: Gender | T2: Date of First Appointment | W2: Date of First Appointment | X2: Confirmation Letter Issued | Y2: Contract Letter Issued
R3: Age
N4: Date | O4: Month | P4: Year | T4: Date | U4: Month | V4: Year
A5: 2 | B5: 051 | C5: 200 | D5: 0026 | E5: 2/051/200/0026 | F5: Confirmed | G5: Vindya Silva | H5: Accountant | I5: 94/39, Pohorabawatta, Aluthambalama, Kosgama | J5: 785561457v | K5: Roman Catholic | L5: 0717755248 | M5: vindya412@gmail.com | N5: 25 | O5: 02 | P5: 1978 | Q5: 28546 | R5: 45.024658 | S5: Female | T5: 01 | U5: 04 | V5: 2003 | W5: 37712 | Y5: Yes
A6: 2 | B6: 051 | C6: 586 | D6: 0027 | E6: 2/051/586/0027 | F6: Confirmed | G6: Aurilia Koelmeyer | H6: Administrator | I6: 176/K, Vijaya Mw, Athurugiriya | J6: 777870416v | K6: Roman Catholic | L6: 0715849869 | M6: ionikoelmeyer@yahoo.com | N6: 13 | O6: 10 | P6: 1977 | Q6: 28411 | R6: 45.394521 | S6: Female | T6: 05 | U6: 04 | V6: 2013 | W6: 41369 | Y6: Yes
A7: 2 | B7: 051 | C7: 782 | D7: 0028 | E7: 2/051/782/0028 | F7: Confirmed | G7: Sujeeva Siriwardena | H7: Librarian | I7: 420/15C, Weli Road, Thalawathugoda | J7: 655772731v | K7: Roman Catholic | L7: 0778491677 | N7: 17 | O7: 03 | P7: 1965 | Q7: 23818 | R7: 57.978082 | S7: Female | T7: 02 | U7: 09 | V7: 2019 | W7: 43710 | Y7: Yes
A8: 2 | B8: 051 | C8: 791 | D8: 0029 | E8: 2/051/791/0029 | F8: Confirmed | G8: Vivian Saverymuthapulle | H8: Accounts Assistant | I8: 234/5, Kuruduwatte 2nd lane, Avariwatte Rd, Wattala | J8: 533253350v | K8: Roman Catholic | L8: 0777176040 | M8: viviansavery@yahoo.com | N8: 20 | O8: 11 | P8: 1953 | Q8: 19683 | R8: 69.306849 | S8: Male | T8: 02 | U8: 01 | V8: 2020 | W8: 43832 | Y8: Yes
A9: 2 | B9: 052 | C9: 788 | D9: 0106 | E9: 2/052/788/0106 | G9: Mihindukulasuriya Subash Jeewantha Kurera | H9: Librarian | I9: No. 6/2, Pitipana Street, Negombo. | J9: 980994287v | K9: Catholic | L9: 0702098728 | M9: subashkurera7@gmail.com | N9: 8 | O9: 4 | P9: 1998 | Q9: 35893 | R9: 24.89589 | S9: Male | T9: 3 | U9: 1 | V9: 2020 | W9: 43833 | X9: Yes
A10: 2 | B10: 052 | C10: 861 | D10: 0123 | E10: 2/052/861/0123 | G10: T Sumudu S Perera | H10: Lab Assistant | I10: No. 629, Daluwakotuwa, Kochchikade. | J10: 975411540v | K10: Catholic | L10: 761936351 | M10: sumuduperera54@gmail.com | N10: 10 | O10: 2 | P10: 1997 | Q10: 35471 | R10: 26.052055 | S10: Female | T10: 6 | U10: 6 | V10: 2022 | W10: 44718
A11: 2 | B11: 053 | C11: 018 | D11: 0163 | E11: 2/053/018/0163 | F11: Confirmed | G11: Edirisinghe Mudiyanselage Dilini Rasika Edirisinghe | H11: Assistant Accountant | I11: No 276/7, Sugatharama Road, Seeduwa | J11: 747461899V | K11: Roman Catholic | L11: 712460748 | M11: dilinirasika74@gmail.com | N11: 2 | O11: 9 | P11: 1974 | Q11: 27274 | R11: 48.509589 | S11: Female | T11: 1 | U11: 3 | V11: 2011 | W11: 41288 | Y11: YES
A12: 2 | B12: 053 | C12: 034 | D12: 0165 | E12: 2/053/034/0165 | F12: Confirmed | G12: Wishmakarma Manam Muhandiramlage Susithe Edward | H12: Accountant | I12: Susith, Suse Road (West), Wennappuwa | J12: 800172101V | K12: Roman Catholic | L12: 777892661 | M12: eddieed9@gmail.com | N12: 17 | O12: 1 | P12: 1980 | Q12: 29237 | R12: 43.131507 | S12: Male | T12: 14 | U12: 9 | V12: 2012 | W12: 41288 | Y12: YES
A13: 2 | B13: 053 | C13: 037 | D13: 0166 | E13: 2/053/037/0166 | F13: Confirmed | G13: Mahamuge Charith Srimal Fernando | H13: Assistant Administrative Officer | I13: No. 18, Nirmala Mawatha, 8th Lane, Katuwapitiya, Negombo | J13: 853481380V | K13: Roman Catholic | L13: 714436551, 775416955 | M13: charithsrimal123@gmail.com | N13: 13 | O13: 12 | P13: 1985 | Q13: 31394 | R13: 37.221918 | S13: Male | T13: 6 | U13: 8 | V13: 2012 | W13: 41288 | Y13: YES
A14: 2 | B14: 053 | C14: 042 | D14: 0169 | E14: 2/053/042/0169 | F14: Confirmed | G14: Paul Peter Dilan Alex | H14: Manager - It | I14: No 14/7, Dewala Road , Hendala, Wattala | J14: 842483581V | K14: Roman Catholic | L14: 715776211, 715742874 | M14: dilanalex@gmail.com | N14: 4 | O14: 9 | P14: 1984 | Q14: 30929 | R14: 38.49589 | S14: Male | T14: 10 | U14: 1 | V14: 2013 | W14: 41288 | Y14: YES
A15: 2 | B15: 053 | C15: 082 | D15: 0178 | E15: 2/053/082/0178 | F15: N/A | G15: Robert Haemish Pemsiri De Silva | H15: Office Helper | I15: No. 57/1, Baseline Road, Amandoluwa, Seeduwa | J15: 391340668V | K15: Roman Catholic | L15: 778518615 | M15: N/A | N15: 13 | O15: 5 | P15: 1939 | Q15: 14378 | R15: 83.841096 | S15: Male | T15: 1 | U15: 9 | V15: 2014 | W15: 41288
A16: 2 | B16: 053 | C16: 101 | D16: 0180 | E16: 2/053/101/0180 | F16: Confirmed | G16: Thaleirathna Mudalige Don Tyronne Wickramasekara | H16: Assistant Academic Coordinator | I16: No. 10/1, Senasungoda, Pugoda | J16: 782880403V | K16: Roman Catholic | L16: 773971343 | M16: calistus178@gmail.com | N16: 14 | O16: 10 | P16: 1978 | Q16: 28777 | R16: 44.391781 | S16: Male | T16: 2 | U16: 5 | V16: 2016 | W16: 41288 | Y16: YES
A17: 2 | B17: 053 | C17: 117 | D17: 0183 | E17: 2/053/117/0183 | F17: Confirmed | G17: Kalinga Prabuddi Shamel Silva | H17: Assistant Manager-It | I17: No.84,Visakawatta ,Ekala, Jaela | J17: 933643182V | K17: Roman Catholic | L17: 773344000 | M17: shamelsilvash@gmail.com | N17: 29 | O17: 12 | P17: 1993 | Q17: 34332 | R17: 29.172603 | S17: Male | T17: 1 | U17: 12 | V17: 2016 | W17: 41288 | Y17: YES
A18: 2 | B18: 053 | C18: 120 | D18: 0186 | E18: 2/053/120/0186 | F18: Confirmed | G18: Bothalage Shayani Dileka Fernando | H18: Assistant Academic Coordinator | I18: No.86,"Chandra",Bandarawatte, Seeduwa | J18: 967583944V | K18: Roman Catholic | L18: 767308697 | M18: shayani.dileka@gmail.com | N18: 14 | O18: 9 | P18: 1996 | Q18: 35322 | R18: 26.460274 | S18: Female | T18: 4 | U18: 1 | V18: 2017 | W18: 41288 | Y18: YES
A19: 2 | B19: 053 | C19: 154 | D19: 0194 | E19: 2/053/154/0194 | F19: Confirmed | G19: Polwattage Saman Jayananda Costa | H19: Front Officer | I19: No. 551, Sathuta, Dandugama, Jaela. | J19: 582570108V | K19: Roman Catholic | L19: 776358856 | M19: N/A | N19: 13 | O19: 9 | P19: 1958 | Q19: 21441 | R19: 64.490411 | S19: Male | T19: 2 | U19: 10 | V19: 2017 | W19: 41288 | Y19: YES
A20: 2 | B20: 053 | C20: 181 | D20: 0203 | E20: 2/053/181/0203 | F20: Confirmed | G20: Nadeesha Dilshanie Rochelle Vanderwall | H20: Examination Officer | I20: 176/D, Gonawila Central, Dankotuwa | J20: 926800795V | K20: Christian | L20: 779298858 | M20: rochellev0628@gmail.com | N20: 28 | O20: 6 | P20: 1992 | Q20: 33783 | R20: 30.676712 | S20: Female | T20: 29 | U20: 8 | V20: 2018 | W20: 41288 | Y20: YES
A21: 2 | B21: 053 | C21: 188 | D21: 0205 | E21: 2/053/188/0205 | F21: Confirmed | G21: Piumi Ishara Jayakody | H21: Accounts Assistant | I21: No. 463/C, Pulluhena, Pamunugama | J21: 967742139V | K21: Roman Catholic | L21: 776767276 | M21: isharajayakody5555@gmail.com | N21: 30 | O21: 9 | P21: 1996 | Q21: 35338 | R21: 26.416438 | S21: Female | T21: 2 | U21: 10 | V21: 2018 | W21: 41288 | Y21: YES
A22: 2 | B22: 053 | C22: 189 | D22: 0206 | E22: 2/053/189/0206 | F22: Confirmed | G22: Palihewadena Arachchige Shehan Asuk Perera Jayawardena | H22: Assistant Accountant | I22: No. 35/13, Dadly Senanayake Mawatha, Negombo | J22: 822994300V | K22: Roman Catholic | L22: 721148029, 767379463 | M22: shehanasuk377@gmail.com | N22: 25 | O22: 10 | P22: 1982 | Q22: 30249 | R22: 40.358904 | S22: Male | T22: 8 | U22: 10 | V22: 2018 | W22: 41288 | Y22: YES
A23: 2 | B23: 053 | C23: 209 | D23: 0214 | E23: 2/053/209/0214 | F23: Contract | G23: Muthunamagonnage Anne Sanasha Nishmi Fernando | H23: Accounts Assistant | I23: No. 84a, St. Jude's Road, Enderamulla, Wattala | J23: 985203709V | K23: Roman Catholic | L23: 770775542 | M23: sanunish1998@gmail.com | N23: 20 | O23: 1 | P23: 1998 | Q23: 35815 | R23: 25.109589 | S23: Female | T23: 11 | U23: 3 | V23: 2019 | W23: 41288
A24: 2 | B24: 053 | C24: 213 | D24: 0216 | E24: 2/053/213/0216 | F24: Confirmed | G24: Wadihiti Hamulage Harshani Mekala | H24: It Assistant | I24: No. 25/41, Kalyani Mawatha, Wattala | J24: 927041413V | K24: Roman Catholic | L24: 779694775 | M24: mekala.stic@gmail.com | N24: 22 | O24: 7 | P24: 1992 | Q24: 33807 | R24: 30.610959 | S24: Female | T24: 14 | U24: 5 | V24: 2019 | W24: 41288 | Y24: YES
A25: 2 | B25: 053 | C25: 215 | D25: 0217 | E25: 2/053/215/0217 | F25: Confirmed | G25: Ruwan Sanjeewa Hettiarachchi | H25: Receptionist | I25: Pitawala Mawatha, Gonawila, Dankotuwa | J25: 831980109V | K25: Roman Catholic | L25: 777623731 | M25: ruwanstcic@yahoo.com | N25: 16 | O25: 7 | P25: 1983 | Q25: 30513 | R25: 39.635616 | S25: Male | T25: 17 | U25: 6 | V25: 2019 | W25: 41288 | Y25: YES
A26: 2 | B26: 053 | C26: 217 | D26: 0218 | E26: 2/053/217/0218 | F26: Confirmed | G26: Warnakulasooriya Emmanuel Nilukshan Fernando | H26: Academic Assistant | I26: No 19/33, Cardinal Coorey Road, Sea Street, Negombo | J26: 199909202608 | K26: Roman Catholic | L26: 771687030 | M26: niluk19990401@gmail.com | N26: 1 | O26: 4 | P26: 1999 | Q26: 36251 | R26: 23.915068 | S26: Male | T26: 26 | U26: 6 | V26: 2019 | W26: 41288 | Y26: YES
A27: 2 | B27: 053 | C27: 235 | D27: 0227 | E27: 2/053/235/0227 | F27: Confirmed | G27: Hathurusinha Arachhilage Don Anuja Nirosh | H27: Academic Assistant | I27: No.482/B, Jayasinhamavatha, Nugape, Pamunugama | J27: 990282196V | K27: Roman Catholic | L27: 776437928 | M27: anujanirosh9@gmail.com | N27: 28 | O27: 1 | P27: 1999 | Q27: 36188 | R27: 24.087671 | S27: Male | T27: 1 | U27: 11 | V27: 2019 | W27: 41288 | Y27: YES
A28: 2 | B28: 053 | C28: 259 | D28: 0238 | E28: 2/053/259/0238 | F28: Confirmed | G28: Menusha Prishani Wijerathna | H28: Administrative Officer | I28: No. 383, Mahawatta, Pamunugama | J28: 956201500V | K28: Roman Catholic | L28: 766639702 | M28: menushaprishani@gmail.com | N28: 29 | O28: 4 | P28: 1995 | Q28: 34818 | R28: 27.841096 | S28: Female | T28: 5 | U28: 10 | V28: 2020 | W28: 41288 | Y28: YES
A29: 2 | B29: 053 | C29: 274 | D29: 0246 | E29: 2/053/274/0246 | F29: Confirmed | G29: Panambarage Madushi Sankalpana Fernando | H29: Accounts Assistant | I29: No. 79, Welihena South, Kochchikade | J29: 968511114V | K29: Roman Catholic | L29: 778274194 | M29: madusaf@gmail.com | N29: 16 | O29: 12 | P29: 1996 | Q29: 35415 | R29: 26.205479 | S29: Female | T29: 29 | U29: 4 | V29: 2021 | W29: 41288 | Y29: YES
A30: 2 | B30: 053 | C30: 275 | D30: 0247 | E30: 2/053/275/0247 | F30: Confirmed | G30: Kariyakarawanage Malini Priyashani Fernando | H30: Admin Office - Assistant | I30: 40/1, St. Nikula Mawatha, South Katuwapitiya , Negombo. | J30: 985080011V | K30: Roman Catholic | L30: 776947299 | M30: maliefdo@gmail.com | N30: 8 | O30: 1 | P30: 1998 | Q30: 35803 | R30: 25.142466 | S30: Female | T30: 10 | U30: 5 | V30: 2021 | W30: 41288 | Y30: YES
A31: 2 | B31: 053 | C31: 320 | D31: 0273 | E31: 2/053/320/0273 | F31: Probation | G31: Manannaidelage Lakshan Udara Fonseka | H31: Admin Office - Assistant | I31: 37/4, St. Xavier Road, Ja-Ela | J31: 961142172V | K31: Roman Catholic | L31: 717670873 | M31: lakshan.udara@gmail.com | N31: 4 | O31: 4 | P31: 1996 | Q31: 35159 | R31: 26.906849 | S31: Male | T31: 10 | U31: 10 | V31: 2022 | W31: 41288
A32: 2 | B32: 54 | C32: 21 | G32: ASLAM DEEN FATHIMA HUSNA | H32: OFFICE | I32: 331/C MAHAHUNUPITIYA, NEGOMBO | J32: 200161201156 | K32: ISLAM | L32: 0761793734 | M32: onlinehus786@gmail.com | N32: 21 | O32: 04 | P32: 2001 | Q32: =DATE(P32,O32,N32) -> 37002 | R32: =(Academic!#REF!-Q32)/365 -> #REF! | S32: FEMALE | T32: 03 | U32: 09 | V32: 2018 | W32: =DATE(V32,U32,T32) -> 43346

Sheet Sheet3
A1: Non-academic Staff of St. Thomas International College
A2: Personal Identification Number | E2: Teacher Identification Number (TIN) | F2: Present Category (Confirmed/Contract) | G2: Name in Full | H2: Designation | I2: Home Address | J2: NIC Number | K2: Religion | L2: Telephone Numbers | M2: Email | N2: Date of Birth | Q2: Date of Birth | S2: Gender | T2: Date of First Appointment | W2: Date of First Appointment | X2: Confirmation Letter Issued | Y2: Contract Letter Issued
R3: Age
N4: Date | O4: Month | P4: Year | T4: Date | U4: Month | V4: Year
A5: 2 | B5: 051 | C5: 200 | D5: 0026 | E5: 2/051/200/0026 | F5: Confirmed | G5: Vindya Silva | H5: Accountant | I5: 94/39, Pohorabawatta, Aluthambalama, Kosgama | J5: 785561457v | K5: Roman Catholic | L5: 0717755248 | M5: vindya412@gmail.com | N5: 25 | O5: 02 | P5: 1978 | Q5: 28546 | R5: 45.024658 | S5: Female | T5: 01 | U5: 04 | V5: 2003 | W5: 37712 | Y5: Yes
A6: 2 | B6: 051 | C6: 586 | D6: 0027 | E6: 2/051/586/0027 | F6: Confirmed | G6: Aurilia Koelmeyer | H6: Administrator | I6: 176/K, Vijaya Mw, Athurugiriya | J6: 777870416v | K6: Roman Catholic | L6: 0715849869 | M6: ionikoelmeyer@yahoo.com | N6: 13 | O6: 10 | P6: 1977 | Q6: 28411 | R6: 45.394521 | S6: Female | T6: 05 | U6: 04 | V6: 2013 | W6: 41369 | Y6: Yes
A7: 2 | B7: 051 | C7: 782 | D7: 0028 | E7: 2/051/782/0028 | F7: Confirmed | G7: Sujeeva Siriwardena | H7: Librarian | I7: 420/15C, Weli Road, Thalawathugoda | J7: 655772731v | K7: Roman Catholic | L7: 0778491677 | N7: 17 | O7: 03 | P7: 1965 | Q7: 23818 | R7: 57.978082 | S7: Female | T7: 02 | U7: 09 | V7: 2019 | W7: 43710 | Y7: Yes
A8: 2 | B8: 051 | C8: 791 | D8: 0029 | E8: 2/051/791/0029 | F8: Confirmed | G8: Vivian Saverymuthapulle | H8: Accounts Assistant | I8: 234/5, Kuruduwatte 2nd lane, Avariwatte Rd, Wattala | J8: 533253350v | K8: Roman Catholic | L8: 0777176040 | M8: viviansavery@yahoo.com | N8: 20 | O8: 11 | P8: 1953 | Q8: 19683 | R8: 69.306849 | S8: Male | T8: 02 | U8: 01 | V8: 2020 | W8: 43832 | Y8: Yes
A9: 2 | B9: 052 | C9: 788 | D9: 0106 | E9: 2/052/788/0106 | G9: Mihindukulasuriya Subash Jeewantha Kurera | H9: Librarian | I9: No. 6/2, Pitipana Street, Negombo. | J9: 980994287v | K9: Catholic | L9: 0702098728 | M9: subashkurera7@gmail.com | N9: 8 | O9: 4 | P9: 1998 | Q9: 35893 | R9: 24.89589 | S9: Male | T9: 3 | U9: 1 | V9: 2020 | W9: 43833 | X9: Yes
A10: 2 | B10: 052 | C10: 861 | D10: 0123 | E10: 2/052/861/0123 | G10: T Sumudu S Perera | H10: Lab Assistant | I10: No. 629, Daluwakotuwa, Kochchikade. | J10: 975411540v | K10: Catholic | L10: 761936351 | M10: sumuduperera54@gmail.com | N10: 10 | O10: 2 | P10: 1997 | Q10: 35471 | R10: 26.052055 | S10: Female | T10: 6 | U10: 6 | V10: 2022 | W10: 44718
A11: 2 | B11: 053 | C11: 018 | D11: 0163 | E11: 2/053/018/0163 | F11: Confirmed | G11: Edirisinghe Mudiyanselage Dilini Rasika Edirisinghe | H11: Assistant Accountant | I11: No 276/7, Sugatharama Road, Seeduwa | J11: 747461899V | K11: Roman Catholic | L11: 712460748 | M11: dilinirasika74@gmail.com | N11: 2 | O11: 9 | P11: 1974 | Q11: 27274 | R11: 48.509589 | S11: Female | T11: 1 | U11: 3 | V11: 2011 | W11: 41288 | Y11: YES
A12: 2 | B12: 053 | C12: 034 | D12: 0165 | E12: 2/053/034/0165 | F12: Confirmed | G12: Wishmakarma Manam Muhandiramlage Susithe Edward | H12: Accountant | I12: Susith, Suse Road (West), Wennappuwa | J12: 800172101V | K12: Roman Catholic | L12: 777892661 | M12: eddieed9@gmail.com | N12: 17 | O12: 1 | P12: 1980 | Q12: 29237 | R12: 43.131507 | S12: Male | T12: 14 | U12: 9 | V12: 2012 | W12: 41288 | Y12: YES
A13: 2 | B13: 053 | C13: 037 | D13: 0166 | E13: 2/053/037/0166 | F13: Confirmed | G13: Mahamuge Charith Srimal Fernando | H13: Assistant Administrative Officer | I13: No. 18, Nirmala Mawatha, 8th Lane, Katuwapitiya, Negombo | J13: 853481380V | K13: Roman Catholic | L13: 714436551, 775416955 | M13: charithsrimal123@gmail.com | N13: 13 | O13: 12 | P13: 1985 | Q13: 31394 | R13: 37.221918 | S13: Male | T13: 6 | U13: 8 | V13: 2012 | W13: 41288 | Y13: YES
A14: 2 | B14: 053 | C14: 042 | D14: 0169 | E14: 2/053/042/0169 | F14: Confirmed | G14: Paul Peter Dilan Alex | H14: Manager - It | I14: No 14/7, Dewala Road , Hendala, Wattala | J14: 842483581V | K14: Roman Catholic | L14: 715776211, 715742874 | M14: dilanalex@gmail.com | N14: 4 | O14: 9 | P14: 1984 | Q14: 30929 | R14: 38.49589 | S14: Male | T14: 10 | U14: 1 | V14: 2013 | W14: 41288 | Y14: YES
A15: 2 | B15: 053 | C15: 082 | D15: 0178 | E15: 2/053/082/0178 | F15: N/A | G15: Robert Haemish Pemsiri De Silva | H15: Office Helper | I15: No. 57/1, Baseline Road, Amandoluwa, Seeduwa | J15: 391340668V | K15: Roman Catholic | L15: 778518615 | M15: N/A | N15: 13 | O15: 5 | P15: 1939 | Q15: 14378 | R15: 83.841096 | S15: Male | T15: 1 | U15: 9 | V15: 2014 | W15: 41288
A16: 2 | B16: 053 | C16: 101 | D16: 0180 | E16: 2/053/101/0180 | F16: Confirmed | G16: Thaleirathna Mudalige Don Tyronne Wickramasekara | H16: Assistant Academic Coordinator | I16: No. 10/1, Senasungoda, Pugoda | J16: 782880403V | K16: Roman Catholic | L16: 773971343 | M16: calistus178@gmail.com | N16: 14 | O16: 10 | P16: 1978 | Q16: 28777 | R16: 44.391781 | S16: Male | T16: 2 | U16: 5 | V16: 2016 | W16: 41288 | Y16: YES
A17: 2 | B17: 053 | C17: 117 | D17: 0183 | E17: 2/053/117/0183 | F17: Confirmed | G17: Kalinga Prabuddi Shamel Silva | H17: Assistant Manager-It | I17: No.84,Visakawatta ,Ekala, Jaela | J17: 933643182V | K17: Roman Catholic | L17: 773344000 | M17: shamelsilvash@gmail.com | N17: 29 | O17: 12 | P17: 1993 | Q17: 34332 | R17: 29.172603 | S17: Male | T17: 1 | U17: 12 | V17: 2016 | W17: 41288 | Y17: YES
A18: 2 | B18: 053 | C18: 120 | D18: 0186 | E18: 2/053/120/0186 | F18: Confirmed | G18: Bothalage Shayani Dileka Fernando | H18: Assistant Academic Coordinator | I18: No.86,"Chandra",Bandarawatte, Seeduwa | J18: 967583944V | K18: Roman Catholic | L18: 767308697 | M18: shayani.dileka@gmail.com | N18: 14 | O18: 9 | P18: 1996 | Q18: 35322 | R18: 26.460274 | S18: Female | T18: 4 | U18: 1 | V18: 2017 | W18: 41288 | Y18: YES
A19: 2 | B19: 053 | C19: 154 | D19: 0194 | E19: 2/053/154/0194 | F19: Confirmed | G19: Polwattage Saman Jayananda Costa | H19: Front Officer | I19: No. 551, Sathuta, Dandugama, Jaela. | J19: 582570108V | K19: Roman Catholic | L19: 776358856 | M19: N/A | N19: 13 | O19: 9 | P19: 1958 | Q19: 21441 | R19: 64.490411 | S19: Male | T19: 2 | U19: 10 | V19: 2017 | W19: 41288 | Y19: YES
A20: 2 | B20: 053 | C20: 181 | D20: 0203 | E20: 2/053/181/0203 | F20: Confirmed | G20: Nadeesha Dilshanie Rochelle Vanderwall | H20: Examination Officer | I20: 176/D, Gonawila Central, Dankotuwa | J20: 926800795V | K20: Christian | L20: 779298858 | M20: rochellev0628@gmail.com | N20: 28 | O20: 6 | P20: 1992 | Q20: 33783 | R20: 30.676712 | S20: Female | T20: 29 | U20: 8 | V20: 2018 | W20: 41288 | Y20: YES
A21: 2 | B21: 053 | C21: 188 | D21: 0205 | E21: 2/053/188/0205 | F21: Confirmed | G21: Piumi Ishara Jayakody | H21: Accounts Assistant | I21: No. 463/C, Pulluhena, Pamunugama | J21: 967742139V | K21: Roman Catholic | L21: 776767276 | M21: isharajayakody5555@gmail.com | N21: 30 | O21: 9 | P21: 1996 | Q21: 35338 | R21: 26.416438 | S21: Female | T21: 2 | U21: 10 | V21: 2018 | W21: 41288 | Y21: YES
A22: 2 | B22: 053 | C22: 189 | D22: 0206 | E22: 2/053/189/0206 | F22: Confirmed | G22: Palihewadena Arachchige Shehan Asuk Perera Jayawardena | H22: Assistant Accountant | I22: No. 35/13, Dadly Senanayake Mawatha, Negombo | J22: 822994300V | K22: Roman Catholic | L22: 721148029, 767379463 | M22: shehanasuk377@gmail.com | N22: 25 | O22: 10 | P22: 1982 | Q22: 30249 | R22: 40.358904 | S22: Male | T22: 8 | U22: 10 | V22: 2018 | W22: 41288 | Y22: YES
A23: 2 | B23: 053 | C23: 209 | D23: 0214 | E23: 2/053/209/0214 | F23: Contract | G23: Muthunamagonnage Anne Sanasha Nishmi Fernando | H23: Accounts Assistant | I23: No. 84a, St. Jude's Road, Enderamulla, Wattala | J23: 985203709V | K23: Roman Catholic | L23: 770775542 | M23: sanunish1998@gmail.com | N23: 20 | O23: 1 | P23: 1998 | Q23: 35815 | R23: 25.109589 | S23: Female | T23: 11 | U23: 3 | V23: 2019 | W23: 41288
A24: 2 | B24: 053 | C24: 213 | D24: 0216 | E24: 2/053/213/0216 | F24: Confirmed | G24: Wadihiti Hamulage Harshani Mekala | H24: It Assistant | I24: No. 25/41, Kalyani Mawatha, Wattala | J24: 927041413V | K24: Roman Catholic | L24: 779694775 | M24: mekala.stic@gmail.com | N24: 22 | O24: 7 | P24: 1992 | Q24: 33807 | R24: 30.610959 | S24: Female | T24: 14 | U24: 5 | V24: 2019 | W24: 41288 | Y24: YES
A25: 2 | B25: 053 | C25: 215 | D25: 0217 | E25: 2/053/215/0217 | F25: Confirmed | G25: Ruwan Sanjeewa Hettiarachchi | H25: Receptionist | I25: Pitawala Mawatha, Gonawila, Dankotuwa | J25: 831980109V | K25: Roman Catholic | L25: 777623731 | M25: ruwanstcic@yahoo.com | N25: 16 | O25: 7 | P25: 1983 | Q25: 30513 | R25: 39.635616 | S25: Male | T25: 17 | U25: 6 | V25: 2019 | W25: 41288 | Y25: YES
A26: 2 | B26: 053 | C26: 217 | D26: 0218 | E26: 2/053/217/0218 | F26: Confirmed | G26: Warnakulasooriya Emmanuel Nilukshan Fernando | H26: Academic Assistant | I26: No 19/33, Cardinal Coorey Road, Sea Street, Negombo | J26: 199909202608 | K26: Roman Catholic | L26: 771687030 | M26: niluk19990401@gmail.com | N26: 1 | O26: 4 | P26: 1999 | Q26: 36251 | R26: 23.915068 | S26: Male | T26: 26 | U26: 6 | V26: 2019 | W26: 41288 | Y26: YES
A27: 2 | B27: 053 | C27: 235 | D27: 0227 | E27: 2/053/235/0227 | F27: Confirmed | G27: Hathurusinha Arachhilage Don Anuja Nirosh | H27: Academic Assistant | I27: No.482/B, Jayasinhamavatha, Nugape, Pamunugama | J27: 990282196V | K27: Roman Catholic | L27: 776437928 | M27: anujanirosh9@gmail.com | N27: 28 | O27: 1 | P27: 1999 | Q27: 36188 | R27: 24.087671 | S27: Male | T27: 1 | U27: 11 | V27: 2019 | W27: 41288 | Y27: YES
A28: 2 | B28: 053 | C28: 259 | D28: 0238 | E28: 2/053/259/0238 | F28: Confirmed | G28: Menusha Prishani Wijerathna | H28: Administrative Officer | I28: No. 383, Mahawatta, Pamunugama | J28: 956201500V | K28: Roman Catholic | L28: 766639702 | M28: menushaprishani@gmail.com | N28: 29 | O28: 4 | P28: 1995 | Q28: 34818 | R28: 27.841096 | S28: Female | T28: 5 | U28: 10 | V28: 2020 | W28: 41288 | Y28: YES
A29: 2 | B29: 053 | C29: 274 | D29: 0246 | E29: 2/053/274/0246 | F29: Confirmed | G29: Panambarage Madushi Sankalpana Fernando | H29: Accounts Assistant | I29: No. 79, Welihena South, Kochchikade | J29: 968511114V | K29: Roman Catholic | L29: 778274194 | M29: madusaf@gmail.com | N29: 16 | O29: 12 | P29: 1996 | Q29: 35415 | R29: 26.205479 | S29: Female | T29: 29 | U29: 4 | V29: 2021 | W29: 41288 | Y29: YES
A30: 2 | B30: 053 | C30: 275 | D30: 0247 | E30: 2/053/275/0247 | F30: Confirmed | G30: Kariyakarawanage Malini Priyashani Fernando | H30: Admin Office - Assistant | I30: 40/1, St. Nikula Mawatha, South Katuwapitiya , Negombo. | J30: 985080011V | K30: Roman Catholic | L30: 776947299 | M30: maliefdo@gmail.com | N30: 8 | O30: 1 | P30: 1998 | Q30: 35803 | R30: 25.142466 | S30: Female | T30: 10 | U30: 5 | V30: 2021 | W30: 41288 | Y30: YES
A31: 2 | B31: 053 | C31: 320 | D31: 0273 | E31: 2/053/320/0273 | F31: Probation | G31: Manannaidelage Lakshan Udara Fonseka | H31: Admin Office - Assistant | I31: 37/4, St. Xavier Road, Ja-Ela | J31: 961142172V | K31: Roman Catholic | L31: 717670873 | M31: lakshan.udara@gmail.com | N31: 4 | O31: 4 | P31: 1996 | Q31: 35159 | R31: 26.906849 | S31: Male | T31: 10 | U31: 10 | V31: 2022 | W31: 41288

Sheet Support Staff
A2: Personal Identification Number | E2: Teacher Identification Number (TIN) | F2: Present Category (Confirmed/Contract) | G2: Name in Full | H2: Designation | I2: Home Address | J2: NIC Number | K2: Religion | L2: Telephone Numbers | M2: Email | N2: Date of Birth | Q2: Date of Birth | S2: Gender | T2: Date of First Appointment | W2: Date of First Appointment | X2: Confirmation Letter Issued | Y2: Contract Letter Issued
R3: Age
N4: Date | O4: Month | P4: Year | T4: Date | U4: Month | V4: Year
A5: 3 | B5: 051 | C5: 424 | D5: 0030 | E5: 3/051/424/0030 | F5: Confirmed | G5: Kumuduni Malkanthi | H5: Support Staff | I5: 42, Waishakya Mw, Rajagiriya | J5: 676002510v | K5: Buddhist | L5: 0754410628 | N5: 09 | O5: 04 | P5: 1967 | Q5: 24571 | R5: 55.915068 | S5: Female | T5: 20 | U5: 04 | V5: 2009 | W5: 39923 | Y5: Yes
A6: 3 | B6: 051 | C6: 685 | D6: 0031 | E6: 3/051/685/0031 | F6: Confirmed | G6: Deepika Lakmali | H6: Support Staff | I6: 1033/D, Thalangama South, Nagahamulla, Battaramulla | J6: 825032754v | K6: Roman Catholic | L6: 0752964196 | N6: 03 | O6: 01 | P6: 1982 | Q6: 29954 | R6: 41.167123 | S6: Female | T6: 01 | U6: 02 | V6: 2016 | W6: 42401 | Y6: Yes
A7: 3 | B7: 051 | C7: 723 | D7: 0032 | E7: 3/051/723/0032 | F7: Confirmed | G7: Sasikala Sewwandi | H7: Support Staff | I7: 1033/A, Thalangama South, Nagahamulla, Battaramulla | J7: 948344785v | K7: Buddhist | L7: 0721375235 | N7: 29 | O7: 11 | P7: 1994 | Q7: 34667 | R7: 28.254795 | S7: Female | T7: 04 | U7: 09 | V7: 2017 | W7: 42982 | Y7: Yes
A8: 3 | B8: 051 | C8: xxx | D8: 0033 | E8: 3/051/xxx/0033 | F8: Contract | G8: H I David | H8: Support Staff | I8: 4/270, Nawarohala Rd, Mulleriyawa | J8: 531841921v | K8: Buddhist | L8: 0717951767 | N8: 02 | O8: 07 | P8: 1953 | Q8: 19542 | R8: 69.693151 | S8: Male | T8: 01 | U8: 03 | V8: 2016 | W8: 42430 | Y8: No
